"""
Network Failure Tests

Enterprise-level tests for network failure scenarios including:
- DNS resolution failures
- SSL/TLS certificate issues
- Network timeouts
- Connection failures
- Proxy issues
- Network congestion
"""

import pytest
import asyncio
import socket
import ssl
import time
from unittest.mock import patch, MagicMock, AsyncMock
import aiohttp
import requests
from aiohttp import ClientTimeout, ServerTimeoutError
import sys
from pathlib import Path

# Add project root to path
project_root = Path(__file__).parent.parent
sys.path.insert(0, str(project_root))


class NetworkFailureSimulator:
    """Simulator for various network failure conditions"""

    def __init__(self):
        self.mock_responses = []

    def simulate_dns_failure(self, hostname: str):
        """Simulate DNS resolution failure"""
        original_getaddrinfo = socket.getaddrinfo

        def failing_getaddrinfo(host, *args, **kwargs):
            if host == hostname:
                raise socket.gaierror("Name resolution failure")
            return original_getaddrinfo(host, *args, **kwargs)

        return patch('socket.getaddrinfo', side_effect=failing_getaddrinfo)

    def simulate_connection_timeout(self):
        """Simulate connection timeout"""
        def timeout_connect(*args, **kwargs):
            time.sleep(35)  # Longer than typical timeouts
            raise ConnectionError("Connection timed out")

        return patch('socket.create_connection', side_effect=timeout_connect)

    def simulate_ssl_failure(self, cert_error: str = "certificate verify failed"):
        """Simulate SSL certificate validation failure"""
        def failing_ssl_wrap(*args, **kwargs):
            raise ssl.SSLCertVerificationError(cert_error)

        return patch('ssl.create_default_context', return_value=MagicMock())


class TestDNSFailureScenarios:
    """Tests for DNS resolution failure scenarios"""

    @pytest.fixture
    def network_simulator(self):
        """Network failure simulator"""
        return NetworkFailureSimulator()

    @pytest.mark.network
    @pytest.mark.resilience
    def test_dns_resolution_failure_handling(self, network_simulator):
        """Test graceful handling of DNS resolution failures"""
        with network_simulator.simulate_dns_failure("api.example.com"):
            # Test DNS resolution failure
            with pytest.raises(socket.gaierror, match="Name resolution failure"):
                socket.getaddrinfo("api.example.com", 443)

    @pytest.mark.network
    @pytest.mark.asyncio
    async def test_dns_failure_with_retry_logic(self, network_simulator):
        """Test DNS failure with retry logic"""
        retry_count = 0
        max_retries = 3

        async def failing_dns_lookup():
            nonlocal retry_count
            retry_count += 1
            if retry_count <= max_retries:
                raise socket.gaierror("Temporary DNS failure")
            return [("mock", "result")]

        # Simulate DNS failure with eventual success
        with patch('socket.getaddrinfo', side_effect=failing_dns_lookup):
            result = None
            for attempt in range(max_retries + 1):
                try:
                    result = socket.getaddrinfo("api.example.com", 443)
                    break
                except socket.gaierror:
                    if attempt < max_retries:
                        await asyncio.sleep(0.1 * (2 ** attempt))  # Exponential backoff
                    else:
                        raise

            assert result is not None
            assert retry_count == max_retries + 1

    @pytest.mark.network
    def test_dns_cache_poisoning_simulation(self):
        """Test handling of DNS cache poisoning scenarios"""
        # Mock DNS cache with poisoned entries
        dns_cache = {
            "trusted.example.com": "192.168.1.100",  # Poisoned IP
            "malicious.example.com": "10.0.0.1"
        }

        def poisoned_getaddrinfo(host, *args, **kwargs):
            if host in dns_cache:
                # Return fake result
                return [(2, 1, 6, '', (dns_cache[host], 443))]
            raise socket.gaierror("Name not found")

        with patch('socket.getaddrinfo', side_effect=poisoned_getaddrinfo):
            # Should detect and handle suspicious DNS responses
            result = socket.getaddrinfo("trusted.example.com", 443)
            assert len(result) > 0
            # In real implementation, would validate IP against known good IPs


class TestSSLTLSCertificateFailures:
    """Tests for SSL/TLS certificate validation failures"""

    @pytest.mark.security
    @pytest.mark.network
    def test_expired_certificate_handling(self, network_simulator):
        """Test handling of expired SSL certificates"""
        with network_simulator.simulate_ssl_failure("certificate has expired"):
            with pytest.raises(ssl.SSLCertVerificationError, match="certificate has expired"):
                # Simulate SSL handshake
                raise ssl.SSLCertVerificationError("certificate has expired")

    @pytest.mark.security
    @pytest.mark.network
    def test_self_signed_certificate_rejection(self, network_simulator):
        """Test rejection of self-signed certificates"""
        with network_simulator.simulate_ssl_failure("self-signed certificate"):
            with pytest.raises(ssl.SSLCertVerificationError, match="self-signed certificate"):
                raise ssl.SSLCertVerificationError("self-signed certificate")

    @pytest.mark.security
    @pytest.mark.network
    def test_certificate_chain_validation_failure(self, network_simulator):
        """Test certificate chain validation failures"""
        with network_simulator.simulate_ssl_failure("unable to get local issuer certificate"):
            with pytest.raises(ssl.SSLCertVerificationError, match="unable to get local issuer certificate"):
                raise ssl.SSLCertVerificationError("unable to get local issuer certificate")

    @pytest.mark.security
    @pytest.mark.network
    def test_ssl_downgrade_attack_simulation(self):
        """Test detection of SSL downgrade attacks"""
        # Simulate protocol downgrade attempt
        def mock_ssl_context(protocol=None):
            if protocol and protocol < ssl.PROTOCOL_TLSv1_2:
                raise ssl.SSLError("Protocol too weak")
            return MagicMock()

        with patch('ssl.create_default_context', side_effect=mock_ssl_context):
            # Should reject weak protocols
            context = ssl.create_default_context()
            # Simulate weak protocol rejection
            with pytest.raises(ssl.SSLError, match="Protocol too weak"):
                # This would normally fail with weak protocol
                pass


class TestNetworkTimeoutScenarios:
    """Tests for various network timeout scenarios"""

    @pytest.mark.network
    @pytest.mark.resilience
    def test_connection_timeout_handling(self, network_simulator):
        """Test connection timeout handling"""
        with network_simulator.simulate_connection_timeout():
            start_time = time.time()
            with pytest.raises(ConnectionError, match="Connection timed out"):
                # Simulate timeout
                time.sleep(35)  # Should be caught by timeout
                raise ConnectionError("Connection timed out")
            elapsed = time.time() - start_time
            assert elapsed >= 30  # Should take at least 30 seconds

    @pytest.mark.network
    @pytest.mark.asyncio
    async def test_http_request_timeout_handling(self):
        """Test HTTP request timeout handling"""
        async def slow_request():
            await asyncio.sleep(10)  # Simulate slow response
            return {"status": "ok"}

        # Test with short timeout
        with pytest.raises(asyncio.TimeoutError):
            await asyncio.wait_for(slow_request(), timeout=1.0)

    @pytest.mark.network
    @pytest.mark.asyncio
    async def test_aiohttp_timeout_scenarios(self):
        """Test aiohttp timeout scenarios"""
        timeout = ClientTimeout(total=1.0, connect=0.5, sock_read=0.5)

        async def test_timeout_scenario():
            async with aiohttp.ClientSession(timeout=timeout) as session:
                try:
                    # This would normally make a request, but we'll simulate timeout
                    await asyncio.sleep(2.0)  # Exceed timeout
                    return {"status": "should not reach here"}
                except asyncio.TimeoutError:
                    raise ServerTimeoutError("Request timed out")

        with pytest.raises(ServerTimeoutError, match="Request timed out"):
            await test_timeout_scenario()

    @pytest.mark.network
    def test_dns_timeout_simulation(self):
        """Test DNS resolution timeouts"""
        def slow_dns_lookup(*args, **kwargs):
            time.sleep(5)  # Simulate slow DNS
            return [("mock", "result")]

        with patch('socket.getaddrinfo', side_effect=slow_dns_lookup):
            start_time = time.time()
            with pytest.raises(TimeoutError):
                # Set a short timeout for DNS resolution
                import socket
                socket.setdefaulttimeout(1.0)
                socket.getaddrinfo("slow.dns.server", 443)
            elapsed = time.time() - start_time
            assert elapsed < 2.0  # Should timeout quickly


class TestConnectionFailureScenarios:
    """Tests for connection failure scenarios"""

    @pytest.mark.network
    @pytest.mark.resilience
    def test_connection_refused_handling(self):
        """Test handling of connection refused errors"""
        def connection_refused(*args, **kwargs):
            raise ConnectionError("Connection refused")

        with patch('socket.create_connection', side_effect=connection_refused):
            with pytest.raises(ConnectionError, match="Connection refused"):
                socket.create_connection(("127.0.0.1", 12345))

    @pytest.mark.network
    def test_network_unreachable_handling(self):
        """Test handling of network unreachable errors"""
        def network_unreachable(*args, **kwargs):
            raise OSError("Network is unreachable")

        with patch('socket.create_connection', side_effect=network_unreachable):
            with pytest.raises(OSError, match="Network is unreachable"):
                socket.create_connection(("192.168.1.100", 80))

    @pytest.mark.network
    @pytest.mark.asyncio
    async def test_connection_pool_exhaustion_network(self):
        """Test connection pool exhaustion over network"""
        semaphore = asyncio.Semaphore(2)  # Limited connections

        async def limited_connection(attempt_id: int):
            async with semaphore:
                if attempt_id > 2:
                    # Simulate pool exhaustion for later attempts
                    raise ConnectionError(f"Connection pool exhausted for attempt {attempt_id}")
                await asyncio.sleep(0.1)
                return f"Connection {attempt_id} successful"

        # Test with more concurrent requests than pool allows
        tasks = [limited_connection(i) for i in range(5)]
        results = await asyncio.gather(*tasks, return_exceptions=True)

        successful = [r for r in results if not isinstance(r, Exception)]
        failed = [r for r in results if isinstance(r, Exception)]

        assert len(successful) == 2  # Only 2 allowed through semaphore
        assert len(failed) == 3  # 3 should fail with pool exhaustion


class TestProxyFailureScenarios:
    """Tests for proxy-related network failures"""

    @pytest.mark.network
    def test_proxy_connection_failure(self):
        """Test proxy connection failures"""
        def proxy_failure(*args, **kwargs):
            raise ConnectionError("Proxy connection failed")

        with patch('socket.create_connection', side_effect=proxy_failure):
            with pytest.raises(ConnectionError, match="Proxy connection failed"):
                socket.create_connection(("proxy.example.com", 8080))

    @pytest.mark.network
    def test_proxy_authentication_failure(self):
        """Test proxy authentication failures"""
        def proxy_auth_failure(*args, **kwargs):
            raise ConnectionError("Proxy authentication required")

        with patch('socket.create_connection', side_effect=proxy_auth_failure):
            with pytest.raises(ConnectionError, match="Proxy authentication required"):
                socket.create_connection(("secure.proxy.example.com", 8080))


class TestNetworkCongestionScenarios:
    """Tests for network congestion scenarios"""

    @pytest.mark.network
    @pytest.mark.stress
    def test_high_latency_simulation(self):
        """Test behavior under high network latency"""
        def high_latency_operation():
            time.sleep(2.0)  # Simulate 2 second latency
            return "response"

        start_time = time.time()
        result = high_latency_operation()
        elapsed = time.time() - start_time

        assert result == "response"
        assert elapsed >= 2.0

    @pytest.mark.network
    @pytest.mark.stress
    def test_packet_loss_simulation(self):
        """Test behavior with simulated packet loss"""
        packet_loss_rate = 0.1  # 10% packet loss

        def unreliable_send(data: bytes) -> bool:
            import random
            return random.random() > packet_loss_rate

        # Simulate sending packets with loss
        total_packets = 100
        successful_sends = 0

        for _ in range(total_packets):
            if unreliable_send(b"test data"):
                successful_sends += 1

        # Should succeed most of the time but not always
        success_rate = successful_sends / total_packets
        assert 0.8 <= success_rate <= 0.95  # Allow for randomness but expect ~90% success


class TestHTTPTimeoutScenarios:
    """HTTP timeout and retry scenarios"""

    @pytest.fixture
    def network_simulator(self):
        """Network failure simulator"""
        return NetworkFailureSimulator()

    @pytest.mark.network
    @pytest.mark.timeout
    @pytest.mark.asyncio
    async def test_http_request_timeout_with_retry(self):
        """Test HTTP request timeouts with retry logic"""
        retry_count = 0
        max_retries = 3

        async def failing_http_request():
            nonlocal retry_count
            retry_count += 1
            if retry_count <= max_retries:
                # Simulate timeout
                await asyncio.sleep(35)  # Longer than timeout
                raise asyncio.TimeoutError("Request timeout")
            return {"status": "success", "data": "response"}

        # Test with timeout and retry
        timeout = 5.0  # 5 second timeout
        result = None

        for attempt in range(max_retries + 1):
            try:
                result = await asyncio.wait_for(failing_http_request(), timeout=timeout)
                break
            except asyncio.TimeoutError:
                if attempt < max_retries:
                    # Exponential backoff
                    await asyncio.sleep(0.5 * (2 ** attempt))
                else:
                    raise

        assert result is not None
        assert result["status"] == "success"
        assert retry_count == max_retries + 1

    @pytest.mark.network
    @pytest.mark.timeout
    @pytest.mark.asyncio
    async def test_http_read_timeout_handling(self):
        """Test handling of HTTP read timeouts"""
        async def slow_response_stream():
            # Send headers quickly
            yield {"status": 200, "headers": {"Content-Type": "application/json"}}

            # But delay the body
            await asyncio.sleep(10)  # Slow body
            yield {"body": '{"data": "slow response"}'}

        read_timeout = 3.0  # 3 second read timeout

        with pytest.raises(asyncio.TimeoutError):
            async def read_with_timeout():
                async for chunk in slow_response_stream():
                    if "body" in chunk:
                        # This should timeout before completion
                        await asyncio.sleep(read_timeout + 1)
                        return chunk
                    await asyncio.sleep(0.1)  # Small delay between chunks

            await asyncio.wait_for(read_with_timeout(), timeout=read_timeout)

    @pytest.mark.network
    @pytest.mark.timeout
    def test_connection_pool_timeout_exhaustion(self):
        """Test connection pool timeout when all connections are busy"""
        import threading

        pool_size = 5
        active_connections = 0
        connection_timeout = 2.0
        pool_lock = threading.Lock()

        def acquire_connection_with_timeout():
            nonlocal active_connections
            start_time = time.time()

            with pool_lock:
                if active_connections >= pool_size:
                    # Pool exhausted - wait for timeout
                    time.sleep(connection_timeout + 0.1)  # Wait past timeout
                    elapsed = time.time() - start_time
                    if elapsed >= connection_timeout:
                        raise Exception("Connection pool timeout - all connections busy")
                    return None

                active_connections += 1
                return f"connection_{active_connections}"

        # Exhaust the connection pool
        connections = []
        for i in range(pool_size):
            conn = acquire_connection_with_timeout()
            connections.append(conn)

        assert len(connections) == pool_size
        assert all(conn is not None for conn in connections)

        # Next request should timeout
        with pytest.raises(Exception, match="Connection pool timeout"):
            acquire_connection_with_timeout()

    @pytest.mark.network
    @pytest.mark.timeout
    @pytest.mark.asyncio
    async def test_http_timeout_with_backoff_strategies(self):
        """Test various backoff strategies for HTTP timeouts"""
        backoff_strategies = {
            "fixed": lambda attempt: 1.0,
            "linear": lambda attempt: attempt * 0.5,
            "exponential": lambda attempt: 0.5 * (2 ** attempt),
            "fibonacci": lambda attempt: [1, 1, 2, 3, 5, 8][attempt] * 0.1,
        }

        for strategy_name, backoff_func in backoff_strategies.items():
            retry_count = 0
            max_retries = 3
            total_delay = 0.0

            async def failing_request():
                nonlocal retry_count
                retry_count += 1
                if retry_count <= max_retries:
                    raise asyncio.TimeoutError(f"Request timeout (attempt {retry_count})")
                return {"success": True}

            # Test retry with specific backoff strategy
            result = None
            for attempt in range(max_retries + 1):
                try:
                    result = await asyncio.wait_for(failing_request(), timeout=2.0)
                    break
                except asyncio.TimeoutError:
                    if attempt < max_retries:
                        delay = backoff_func(attempt)
                        total_delay += delay
                        await asyncio.sleep(delay)
                    else:
                        raise

            assert result is not None
            assert result["success"] is True
            assert retry_count == max_retries + 1
            assert total_delay > 0  # Some delay occurred

    @pytest.mark.network
    @pytest.mark.timeout
    def test_http_timeout_circuit_breaker_integration(self):
        """Test HTTP timeout scenarios with circuit breaker integration"""
        class TimeoutCircuitBreaker:
            def __init__(self, failure_threshold=3, timeout_window=60):
                self.failure_count = 0
                self.failure_threshold = failure_threshold
                self.state = "closed"  # closed, open, half_open
                self.last_failure_time = 0
                self.timeout_window = timeout_window

            def call(self, operation):
                if self.state == "open":
                    # Check if we should transition to half-open
                    if time.time() - self.last_failure_time > self.timeout_window:
                        self.state = "half_open"
                    else:
                        raise Exception("Circuit breaker is OPEN due to timeouts")

                try:
                    result = operation()
                    if self.state == "half_open":
                        self.state = "closed"
                        self.failure_count = 0
                    return result
                except Exception as e:
                    self.failure_count += 1
                    self.last_failure_time = time.time()

                    if self.failure_count >= self.failure_threshold:
                        self.state = "open"

                    raise e

        breaker = TimeoutCircuitBreaker()

        # Simulate timeout failures
        timeout_count = 0
        def timeout_operation():
            nonlocal timeout_count
            timeout_count += 1
            raise Exception("Request timeout")

        # First few calls should allow attempts
        for i in range(3):
            with pytest.raises(Exception, match="Request timeout"):
                breaker.call(timeout_operation)

        assert breaker.state == "open"

        # Next call should be blocked by circuit breaker
        with pytest.raises(Exception, match="Circuit breaker is OPEN"):
            breaker.call(timeout_operation)


class TestAdvancedDNSFailureScenarios:
    """Advanced DNS failure and resolution scenarios"""

    @pytest.fixture
    def network_simulator(self):
        """Network failure simulator"""
        return NetworkFailureSimulator()

    @pytest.mark.network
    @pytest.mark.dns
    def test_dns_nxdomain_response_handling(self):
        """Test handling of NXDOMAIN DNS responses"""
        def nxdomain_response(*args, **kwargs):
            # Simulate NXDOMAIN (non-existent domain)
            raise socket.gaierror(-2, "Name or service not known")

        with patch('socket.getaddrinfo', side_effect=nxdomain_response):
            with pytest.raises(socket.gaierror, match="Name or service not known"):
                socket.getaddrinfo("nonexistent-domain-12345.com", 80)

    @pytest.mark.network
    @pytest.mark.dns
    def test_dns_servfail_response_handling(self):
        """Test handling of SERVFAIL DNS responses"""
        def servfail_response(*args, **kwargs):
            # Simulate SERVFAIL (server failure)
            raise socket.gaierror(-3, "Temporary failure in name resolution")

        with patch('socket.getaddrinfo', side_effect=servfail_response):
            with pytest.raises(socket.gaierror, match="Temporary failure"):
                socket.getaddrinfo("servfail-test.com", 80)

    @pytest.mark.network
    @pytest.mark.dns
    def test_dns_cache_poisoning_simulation(self):
        """Test DNS cache poisoning detection and handling"""
        dns_cache = {}
        poisoning_detected = False

        def poisoned_dns_lookup(hostname, *args, **kwargs):
            nonlocal poisoning_detected

            if hostname in dns_cache:
                return dns_cache[hostname]

            # Simulate poisoned response (wrong IP for legitimate domain)
            if hostname == "trusted-site.com":
                # Return wrong IP (should be 1.2.3.4, but poisoned to 5.6.7.8)
                poisoned_result = [("fake", ("5.6.7.8", 80))]
                dns_cache[hostname] = poisoned_result

                # Detect poisoning by checking against known good IPs
                known_good_ips = ["1.2.3.4"]
                returned_ip = poisoned_result[0][1][0]

                if returned_ip not in known_good_ips:
                    poisoning_detected = True
                    raise Exception("DNS cache poisoning detected")

                return poisoned_result

            # Normal response for other domains
            return [("normal", ("192.168.1.1", 80))]

        with patch('socket.getaddrinfo', side_effect=poisoned_dns_lookup):
            # This should detect poisoning and raise exception
            with pytest.raises(Exception, match="DNS cache poisoning detected"):
                socket.getaddrinfo("trusted-site.com", 80)

            assert poisoning_detected

    @pytest.mark.network
    @pytest.mark.dns
    def test_dns_server_unavailability_handling(self):
        """Test handling when DNS servers are unreachable"""
        def unreachable_dns_server(*args, **kwargs):
            # Simulate DNS server timeout/unreachable
            raise socket.gaierror(-110, "Connection timed out")

        with patch('socket.getaddrinfo', side_effect=unreachable_dns_server):
            with pytest.raises(socket.gaierror, match="Connection timed out"):
                socket.getaddrinfo("dns-unreachable.com", 80)

    @pytest.mark.network
    @pytest.mark.dns
    @pytest.mark.asyncio
    async def test_dns_failover_with_multiple_servers(self):
        """Test DNS failover across multiple DNS servers"""
        server_attempts = []

        async def dns_server_attempt(server_index):
            server_attempts.append(server_index)
            if server_index < 2:  # First two servers fail
                raise socket.gaierror(f"DNS server {server_index} unreachable")
            # Third server succeeds
            return [("success", ("10.0.0.1", 80))]

        # Simulate querying multiple DNS servers
        result = None
        dns_servers = [0, 1, 2]  # Three DNS servers

        for server_idx in dns_servers:
            try:
                result = await dns_server_attempt(server_idx)
                break
            except socket.gaierror:
                continue

        assert result is not None
        assert result[0][1][0] == "10.0.0.1"
        assert server_attempts == [0, 1, 2]  # All servers attempted
        assert len(server_attempts) == 3  # Failover occurred